<?xml version="1.0" encoding="UTF-8"?>
<testng-results skipped="1" failed="1" ignored="28" total="30" passed="0">
  <reporter-output>
  </reporter-output>
  <suite name="FREE CRM Application Test Automation Test Suite" duration-ms="25332" started-at="2020-04-11T04:02:23Z" finished-at="2020-04-11T04:02:49Z">
    <groups>
    </groups>
    <test name="Free CRM App Test Cases" duration-ms="25332" started-at="2020-04-11T04:02:23Z" finished-at="2020-04-11T04:02:49Z">
      <class name="com.crm.qa.testcases.LogActivityTest">
        <test-method status="PASS" signature="setUp()[pri:0, instance:com.crm.qa.testcases.LogActivityTest@442675e1]" name="setUp" is-config="true" duration-ms="10260" started-at="2020-04-10T21:02:23Z" finished-at="2020-04-10T21:02:34Z">
          <reporter-output>
          </reporter-output>
        </test-method> <!-- setUp -->
        <test-method status="SKIP" signature="notReached_multipleUsers(java.lang.String)[pri:0, instance:com.crm.qa.testcases.LogActivityTest@442675e1]" name="notReached_multipleUsers" duration-ms="7" started-at="2020-04-10T21:02:34Z" description="Log a Call with Not Reached Scenario. Test Case will be run for multiple profiles." data-provider="multipleUsers" finished-at="2020-04-10T21:02:34Z">
          <params>
            <param index="0">
              <value>
                <![CDATA[0050R000000XRFmQAO]]>
              </value>
            </param>
          </params>
          <exception class="java.lang.NullPointerException">
            <full-stacktrace>
              <![CDATA[java.lang.NullPointerException
	at com.crm.qa.testcases.LogActivityTest.notReached_multipleUsers(LogActivityTest.java:105)
	at sun.reflect.NativeMethodAccessorImpl.invoke0(Native Method)
	at sun.reflect.NativeMethodAccessorImpl.invoke(Unknown Source)
	at sun.reflect.DelegatingMethodAccessorImpl.invoke(Unknown Source)
	at java.lang.reflect.Method.invoke(Unknown Source)
	at org.testng.internal.MethodInvocationHelper.invokeMethod(MethodInvocationHelper.java:108)
	at org.testng.internal.Invoker.invokeMethod(Invoker.java:661)
	at org.testng.internal.Invoker.invokeTestMethod(Invoker.java:869)
	at org.testng.internal.Invoker.invokeTestMethods(Invoker.java:1193)
	at org.testng.internal.TestMethodWorker.invokeTestMethods(TestMethodWorker.java:126)
	at org.testng.internal.TestMethodWorker.run(TestMethodWorker.java:109)
	at org.testng.TestRunner.privateRun(TestRunner.java:744)
	at org.testng.TestRunner.run(TestRunner.java:602)
	at org.testng.SuiteRunner.runTest(SuiteRunner.java:380)
	at org.testng.SuiteRunner.runSequentially(SuiteRunner.java:375)
	at org.testng.SuiteRunner.privateRun(SuiteRunner.java:340)
	at org.testng.SuiteRunner.run(SuiteRunner.java:289)
	at org.testng.SuiteRunnerWorker.runSuite(SuiteRunnerWorker.java:52)
	at org.testng.SuiteRunnerWorker.run(SuiteRunnerWorker.java:86)
	at org.testng.TestNG.runSuitesSequentially(TestNG.java:1301)
	at org.testng.TestNG.runSuitesLocally(TestNG.java:1226)
	at org.testng.TestNG.runSuites(TestNG.java:1144)
	at org.testng.TestNG.run(TestNG.java:1115)
	at org.testng.remote.AbstractRemoteTestNG.run(AbstractRemoteTestNG.java:132)
	at org.testng.remote.RemoteTestNG.initAndRun(RemoteTestNG.java:230)
	at org.testng.remote.RemoteTestNG.main(RemoteTestNG.java:76)
]]>
            </full-stacktrace>
          </exception> <!-- java.lang.NullPointerException -->
          <reporter-output>
          </reporter-output>
        </test-method> <!-- notReached_multipleUsers -->
        <test-method status="PASS" signature="tearDown()[pri:0, instance:com.crm.qa.testcases.LogActivityTest@442675e1]" name="tearDown" is-config="true" duration-ms="667" started-at="2020-04-10T21:02:34Z" finished-at="2020-04-10T21:02:34Z">
          <reporter-output>
          </reporter-output>
        </test-method> <!-- tearDown -->
        <test-method status="PASS" signature="setUp()[pri:0, instance:com.crm.qa.testcases.LogActivityTest@442675e1]" name="setUp" is-config="true" duration-ms="8365" started-at="2020-04-10T21:02:34Z" finished-at="2020-04-10T21:02:43Z">
          <reporter-output>
          </reporter-output>
        </test-method> <!-- setUp -->
        <test-method status="FAIL" signature="notReached_multipleUsers(java.lang.String)[pri:0, instance:com.crm.qa.testcases.LogActivityTest@442675e1]" name="notReached_multipleUsers" duration-ms="0" started-at="2020-04-10T21:02:43Z" description="Log a Call with Not Reached Scenario. Test Case will be run for multiple profiles." data-provider="multipleUsers" finished-at="2020-04-10T21:02:43Z">
          <params>
            <param index="0">
              <value>
                <![CDATA[0050R000000XRFmQAO]]>
              </value>
            </param>
          </params>
          <exception class="java.lang.NullPointerException">
            <full-stacktrace>
              <![CDATA[java.lang.NullPointerException
	at com.crm.qa.testcases.LogActivityTest.notReached_multipleUsers(LogActivityTest.java:105)
	at sun.reflect.NativeMethodAccessorImpl.invoke0(Native Method)
	at sun.reflect.NativeMethodAccessorImpl.invoke(Unknown Source)
	at sun.reflect.DelegatingMethodAccessorImpl.invoke(Unknown Source)
	at java.lang.reflect.Method.invoke(Unknown Source)
	at org.testng.internal.MethodInvocationHelper.invokeMethod(MethodInvocationHelper.java:108)
	at org.testng.internal.Invoker.invokeMethod(Invoker.java:661)
	at org.testng.internal.Invoker.retryFailed(Invoker.java:1014)
	at org.testng.internal.Invoker.invokeTestMethods(Invoker.java:1215)
	at org.testng.internal.TestMethodWorker.invokeTestMethods(TestMethodWorker.java:126)
	at org.testng.internal.TestMethodWorker.run(TestMethodWorker.java:109)
	at org.testng.TestRunner.privateRun(TestRunner.java:744)
	at org.testng.TestRunner.run(TestRunner.java:602)
	at org.testng.SuiteRunner.runTest(SuiteRunner.java:380)
	at org.testng.SuiteRunner.runSequentially(SuiteRunner.java:375)
	at org.testng.SuiteRunner.privateRun(SuiteRunner.java:340)
	at org.testng.SuiteRunner.run(SuiteRunner.java:289)
	at org.testng.SuiteRunnerWorker.runSuite(SuiteRunnerWorker.java:52)
	at org.testng.SuiteRunnerWorker.run(SuiteRunnerWorker.java:86)
	at org.testng.TestNG.runSuitesSequentially(TestNG.java:1301)
	at org.testng.TestNG.runSuitesLocally(TestNG.java:1226)
	at org.testng.TestNG.runSuites(TestNG.java:1144)
	at org.testng.TestNG.run(TestNG.java:1115)
	at org.testng.remote.AbstractRemoteTestNG.run(AbstractRemoteTestNG.java:132)
	at org.testng.remote.RemoteTestNG.initAndRun(RemoteTestNG.java:230)
	at org.testng.remote.RemoteTestNG.main(RemoteTestNG.java:76)
]]>
            </full-stacktrace>
          </exception> <!-- java.lang.NullPointerException -->
          <reporter-output>
          </reporter-output>
        </test-method> <!-- notReached_multipleUsers -->
        <test-method status="PASS" signature="tearDown()[pri:0, instance:com.crm.qa.testcases.LogActivityTest@442675e1]" name="tearDown" is-config="true" duration-ms="667" started-at="2020-04-10T21:02:48Z" finished-at="2020-04-10T21:02:49Z">
          <reporter-output>
          </reporter-output>
        </test-method> <!-- tearDown -->
      </class> <!-- com.crm.qa.testcases.LogActivityTest -->
    </test> <!-- Free CRM App Test Cases -->
  </suite> <!-- FREE CRM Application Test Automation Test Suite -->
</testng-results>
